<robot name="rhobetto">
<link name="pelvis">
<visual>
<origin xyz="-3.2093940488156593915e-15 -0.11999999999994814814 -1.8168583601685873882e-14" rpy="-2.3968608495115065641e-13 7.330080169662416939e-27 3.7448197579713227193e-14" />
<geometry>
<mesh filename="package:///pelvis_bearing_housing.stl"/>
</geometry>
<material name="pelvis_bearing_housing_material">
<color rgba="0.26274509803921569651 0.28235294117647058432 0.30196078431372547213 1.0"/>
</material>
</visual>
<collision>
<origin xyz="-3.2093940488156593915e-15 -0.11999999999994814814 -1.8168583601685873882e-14" rpy="-2.3968608495115065641e-13 7.330080169662416939e-27 3.7448197579713227193e-14" />
<geometry>
<mesh filename="package:///pelvis_bearing_housing.stl"/>
</geometry>
</collision>
<visual>
<origin xyz="-7.6771569062415945483e-15 5.1847415249994797816e-14 -4.6930913795823954671e-14" rpy="-2.3968608495115065641e-13 7.330080169662416939e-27 3.7448197579713227193e-14" />
<geometry>
<mesh filename="package:///pelvis_bearing_housing.stl"/>
</geometry>
<material name="pelvis_bearing_housing_material">
<color rgba="0.26274509803921569651 0.28235294117647058432 0.30196078431372547213 1.0"/>
</material>
</visual>
<collision>
<origin xyz="-7.6771569062415945483e-15 5.1847415249994797816e-14 -4.6930913795823954671e-14" rpy="-2.3968608495115065641e-13 7.330080169662416939e-27 3.7448197579713227193e-14" />
<geometry>
<mesh filename="package:///pelvis_bearing_housing.stl"/>
</geometry>
</collision>
<visual>
<origin xyz="-7.7743014208962957456e-15 5.1847415249994791505e-14 -4.6930913795823954671e-14" rpy="-2.3968608495115065641e-13 7.330080169662416939e-27 3.7448197579713227193e-14" />
<geometry>
<mesh filename="package:///pelvis.stl"/>
</geometry>
<material name="pelvis_material">
<color rgba="0.91764705882352937127 0.91764705882352937127 0.91764705882352937127 1.0"/>
</material>
</visual>
<collision>
<origin xyz="-7.7743014208962957456e-15 5.1847415249994791505e-14 -4.6930913795823954671e-14" rpy="-2.3968608495115065641e-13 7.330080169662416939e-27 3.7448197579713227193e-14" />
<geometry>
<mesh filename="package:///pelvis.stl"/>
</geometry>
</collision>
<inertial>
<origin xyz="0.009349990867296825367 -0.12140913580928421045 0.1671301042834828221" rpy="0 0 0"/>
<mass value="0.51681395261861506896" />
<inertia ixx="0.0019236659941732263488" ixy="6.4249100672645643608e-17"  ixz="9.5670825003526485974e-20" iyy="0.00020583461195036899445" iyz="3.2778285749751589416e-08" izz="0.0020762404268994160209" />
</inertial>
</link>

<link name="trunk">
<inertial>
<origin xyz="0 0 0" rpy="0 0 0" />
<mass value="1e-9" />
<inertia ixx="0" ixy="0" ixz="0" iyy="0" iyz="0" izz="0" />
</inertial>
</link>
<joint name="trunk_frame" type="fixed">
<origin xyz="0.0093499908672967854684 -0.12145115613833781798 0.17549999877808217241" rpy="-2.3968608495115065641e-13 1.224646799220653916e-16 3.7448197579713195639e-14" />
<parent link="pelvis" />
<child link="trunk" />
<axis xyz="0 0 0"/>
</joint>

<link name="left_upper_hip">
<visual>
<origin xyz="0.016249899864201281657 0.10606601717788852191 0.015433982822033398552" rpy="3.1415926535897891192 -0.78539816339741252982 1.5707963267944493602" />
<geometry>
<mesh filename="package:///bearing_cover_1.stl"/>
</geometry>
<material name="bearing_cover_1_material">
<color rgba="0.26274509803921569651 0.28235294117647058432 0.30196078431372547213 1.0"/>
</material>
</visual>
<collision>
<origin xyz="0.016249899864201281657 0.10606601717788852191 0.015433982822033398552" rpy="3.1415926535897891192 -0.78539816339741252982 1.5707963267944493602" />
<geometry>
<mesh filename="package:///bearing_cover_1.stl"/>
</geometry>
</collision>
<visual>
<origin xyz="-0.011249993324299656372 -3.3334446314370325126e-14 0.066500000000009898415" rpy="-3.1415926535897926719 2.6313752754223983936e-17 1.5707963267944460295" />
<geometry>
<mesh filename="package:///rmd_x6.stl"/>
</geometry>
<material name="rmd_x6_material">
<color rgba="0.30196078431372547213 0.30196078431372547213 0.30196078431372547213 1.0"/>
</material>
</visual>
<collision>
<origin xyz="-0.011249993324299656372 -3.3334446314370325126e-14 0.066500000000009898415" rpy="-3.1415926535897926719 2.6313752754223983936e-17 1.5707963267944460295" />
<geometry>
<mesh filename="package:///rmd_x6.stl"/>
</geometry>
</collision>
<visual>
<origin xyz="-0.0093499908672986607044 -0.061399903679188523598 0.17949999877805611348" rpy="3.141592653589793116 -3.6031582164715019713e-15 1.0164091790443062003e-13" />
<geometry>
<mesh filename="package:///upper_hip_4.stl"/>
</geometry>
<material name="upper_hip_4_material">
<color rgba="0.26274509803921569651 0.28235294117647058432 0.30196078431372547213 1.0"/>
</material>
</visual>
<collision>
<origin xyz="-0.0093499908672986607044 -0.061399903679188523598 0.17949999877805611348" rpy="3.141592653589793116 -3.6031582164715019713e-15 1.0164091790443062003e-13" />
<geometry>
<mesh filename="package:///upper_hip_4.stl"/>
</geometry>
</collision>
<visual>
<origin xyz="-0.0093499908672977170149 -0.061399903679188683192 0.17949999877805611348" rpy="3.141592653589793116 4.4882138689742022643e-16 1.0164091790443131423e-13" />
<geometry>
<mesh filename="package:///upper_hip_2.stl"/>
</geometry>
<material name="upper_hip_2_material">
<color rgba="0.91764705882352937127 0.91764705882352937127 0.91764705882352937127 1.0"/>
</material>
</visual>
<collision>
<origin xyz="-0.0093499908672977170149 -0.061399903679188683192 0.17949999877805611348" rpy="3.141592653589793116 4.4882138689742022643e-16 1.0164091790443131423e-13" />
<geometry>
<mesh filename="package:///upper_hip_2.stl"/>
</geometry>
</collision>
<visual>
<origin xyz="-0.0093499908672999374609 -0.061399903678899914183 0.17949999877809996729" rpy="3.141592653589793116 4.5252399253321812021e-16 4.7770550711187892187e-30" />
<geometry>
<mesh filename="package:///upper_hip_3.stl"/>
</geometry>
<material name="upper_hip_3_material">
<color rgba="0.26274509803921569651 0.28235294117647058432 0.30196078431372547213 1.0"/>
</material>
</visual>
<collision>
<origin xyz="-0.0093499908672999374609 -0.061399903678899914183 0.17949999877809996729" rpy="3.141592653589793116 4.5252399253321812021e-16 4.7770550711187892187e-30" />
<geometry>
<mesh filename="package:///upper_hip_3.stl"/>
</geometry>
</collision>
<visual>
<origin xyz="-0.0093499908672999374609 -0.061399903678899914183 0.17949999877809996729" rpy="-3.141592653589793116 3.912916525759393916e-16 -3.5885975238711362505e-30" />
<geometry>
<mesh filename="package:///upper_hip_5.stl"/>
</geometry>
<material name="upper_hip_5_material">
<color rgba="0.26274509803921569651 0.28235294117647058432 0.30196078431372547213 1.0"/>
</material>
</visual>
<collision>
<origin xyz="-0.0093499908672999374609 -0.061399903678899914183 0.17949999877809996729" rpy="-3.141592653589793116 3.912916525759393916e-16 -3.5885975238711362505e-30" />
<geometry>
<mesh filename="package:///upper_hip_5.stl"/>
</geometry>
</collision>
<visual>
<origin xyz="-0.037849979154978695417 -0.1060660171782459027 0.22756601717793384365" rpy="-1.9008401864760186142e-15 -0.7853981633974059795 1.5707963267948563679" />
<geometry>
<mesh filename="package:///bearing_cover_1.stl"/>
</geometry>
<material name="bearing_cover_1_material">
<color rgba="0.26274509803921569651 0.28235294117647058432 0.30196078431372547213 1.0"/>
</material>
</visual>
<collision>
<origin xyz="-0.037849979154978695417 -0.1060660171782459027 0.22756601717793384365" rpy="-1.9008401864760186142e-15 -0.7853981633974059795 1.5707963267948563679" />
<geometry>
<mesh filename="package:///bearing_cover_1.stl"/>
</geometry>
</collision>
<visual>
<origin xyz="-0.0093499908672999374609 -0.061399903678899914183 0.17949999877809996729" rpy="-3.141592653589793116 6.0604247301017531101e-16 -3.8857805861878191218e-16" />
<geometry>
<mesh filename="package:///upper_hip_1.stl"/>
</geometry>
<material name="upper_hip_1_material">
<color rgba="0.91764705882352937127 0.91764705882352937127 0.91764705882352937127 1.0"/>
</material>
</visual>
<collision>
<origin xyz="-0.0093499908672999374609 -0.061399903678899914183 0.17949999877809996729" rpy="-3.141592653589793116 6.0604247301017531101e-16 -3.8857805861878191218e-16" />
<geometry>
<mesh filename="package:///upper_hip_1.stl"/>
</geometry>
</collision>
<inertial>
<origin xyz="0.0023702542588580344241 0.00027244096508671994481 0.071906008336858964758" rpy="0 0 0"/>
<mass value="0.47353711718592900182" />
<inertia ixx="0.0005369578565435997354" ixy="1.6441178212298225028e-06"  ixz="4.7498767206051887364e-05" iyy="0.00053238399884361728865" iyz="-4.5985970847444550483e-06" izz="0.00029813449379955330549" />
</inertial>
</link>

<link name="motor_pulley">
<visual>
<origin xyz="0 0 -0.019400000000000021394" rpy="-1.570796326794896558 -1.570796326794896558 0" />
<geometry>
<mesh filename="package:///motor_pulley.stl"/>
</geometry>
<material name="motor_pulley_material">
<color rgba="0.69019607843137253944 0.69019607843137253944 0.69019607843137253944 1.0"/>
</material>
</visual>
<collision>
<origin xyz="0 0 -0.019400000000000021394" rpy="-1.570796326794896558 -1.570796326794896558 0" />
<geometry>
<mesh filename="package:///motor_pulley.stl"/>
</geometry>
</collision>
<inertial>
<origin xyz="-6.0664442683288490972e-16 4.6478062022552347901e-05 -0.010286242910584404014" rpy="0 0 0"/>
<mass value="0.068767168773007744664" />
<inertia ixx="9.6751984178822625322e-06" ixy="-1.376428539288238051e-21"  ixz="-9.1817047993386071911e-21" iyy="9.6433853220652390932e-06" iyz="-2.7667478259045696394e-08" izz="1.5466315743353511406e-05" />
</inertial>
</link>

<joint name="left_hip_roll_1" type="revolute">
<origin xyz="-0.011249993324299658107 -3.3334446314370325126e-14 0.066500000000009912293" rpy="-1.5707963267948970021 -2.6313752692175340574e-17 -1.5707963267953473085" />
<parent link="left_upper_hip" />
<child link="motor_pulley" />
<axis xyz="0 0 1"/>
<limit effort="1" velocity="20" />
<joint_properties friction="0.0"/>
</joint>

<link name="left_lower_hip">
<visual>
<origin xyz="0.061399903678899907244 0.057999998778099998153 -0.026999998778099994906" rpy="1.570796326794896558 1.570796326794896558 0" />
<geometry>
<mesh filename="package:///inner_hip.stl"/>
</geometry>
<material name="inner_hip_material">
<color rgba="0.26274509803921569651 0.28235294117647058432 0.30196078431372547213 1.0"/>
</material>
</visual>
<collision>
<origin xyz="0.061399903678899907244 0.057999998778099998153 -0.026999998778099994906" rpy="1.570796326794896558 1.570796326794896558 0" />
<geometry>
<mesh filename="package:///inner_hip.stl"/>
</geometry>
</collision>
<visual>
<origin xyz="-0.018000000000009869217 0.057999998778100178565 -0.026999998778098929786" rpy="-1.5127306466214740796e-14 -0.52359877559831902172 -1.5707963267948890085" />
<geometry>
<mesh filename="package:///rmd_x6.stl"/>
</geometry>
<material name="rmd_x6_material">
<color rgba="0.30196078431372547213 0.30196078431372547213 0.30196078431372547213 1.0"/>
</material>
</visual>
<collision>
<origin xyz="-0.018000000000009869217 0.057999998778100178565 -0.026999998778098929786" rpy="-1.5127306466214740796e-14 -0.52359877559831902172 -1.5707963267948890085" />
<geometry>
<mesh filename="package:///rmd_x6.stl"/>
</geometry>
</collision>
<inertial>
<origin xyz="0.00016613532815910639589 0.055315628137895422878 -0.026434310255799207262" rpy="0 0 0"/>
<mass value="0.37002551285788642943" />
<inertia ixx="0.00027176429121269102826" ixy="9.5842279711218867697e-07"  ixz="2.7708589239784076332e-07" iyy="0.00016628895892409402434" iyz="3.8771098302006629381e-06" izz="0.00019082503390196466726" />
</inertial>
</link>

<link name="left_femur">
<visual>
<origin xyz="-6.4989503856405293723e-16 -4.7361719415863419403e-15 -0.032900000000045240278" rpy="-1.5707963267948779063 2.1649348980325810629e-15 -7.7937656328685812433e-14" />
<geometry>
<mesh filename="package:///rmd_x6.stl"/>
</geometry>
<material name="rmd_x6_material">
<color rgba="0.30196078431372547213 0.30196078431372547213 0.30196078431372547213 1.0"/>
</material>
</visual>
<collision>
<origin xyz="-6.4989503856405293723e-16 -4.7361719415863419403e-15 -0.032900000000045240278" rpy="-1.5707963267948779063 2.1649348980325810629e-15 -7.7937656328685812433e-14" />
<geometry>
<mesh filename="package:///rmd_x6.stl"/>
</geometry>
</collision>
<visual>
<origin xyz="-6.9152840198750814041e-16 -4.6147412982679559773e-15 -0.032900000000045268034" rpy="-1.5707963267948779063 2.1649348980325810629e-15 -7.7937656328685812433e-14" />
<geometry>
<mesh filename="package:///inner_femur.stl"/>
</geometry>
<material name="inner_femur_material">
<color rgba="0.91764705882352937127 0.91764705882352937127 0.91764705882352937127 1.0"/>
</material>
</visual>
<collision>
<origin xyz="-6.9152840198750814041e-16 -4.6147412982679559773e-15 -0.032900000000045268034" rpy="-1.5707963267948779063 2.1649348980325810629e-15 -7.7937656328685812433e-14" />
<geometry>
<mesh filename="package:///inner_femur.stl"/>
</geometry>
</collision>
<visual>
<origin xyz="1.0746428927539622478e-15 8.1809379572892084194e-15 0.047999893188570952329" rpy="1.5707963267949058839 -1.0957901253052082297e-13 3.1415926535896701033" />
<geometry>
<mesh filename="package:///bearing_cover_1.stl"/>
</geometry>
<material name="bearing_cover_1_material">
<color rgba="0.26274509803921569651 0.28235294117647058432 0.30196078431372547213 1.0"/>
</material>
</visual>
<collision>
<origin xyz="1.0746428927539622478e-15 8.1809379572892084194e-15 0.047999893188570952329" rpy="1.5707963267949058839 -1.0957901253052082297e-13 3.1415926535896701033" />
<geometry>
<mesh filename="package:///bearing_cover_1.stl"/>
</geometry>
</collision>
<visual>
<origin xyz="-6.4989503856405293723e-16 -4.7361719415863419403e-15 -0.032900000000045240278" rpy="-1.5707963267948779063 2.1649348980325810629e-15 -7.7937656328685812433e-14" />
<geometry>
<mesh filename="package:///outer_femur.stl"/>
</geometry>
<material name="outer_femur_material">
<color rgba="0.91764705882352937127 0.91764705882352937127 0.91764705882352937127 1.0"/>
</material>
</visual>
<collision>
<origin xyz="-6.4989503856405293723e-16 -4.7361719415863419403e-15 -0.032900000000045240278" rpy="-1.5707963267948779063 2.1649348980325810629e-15 -7.7937656328685812433e-14" />
<geometry>
<mesh filename="package:///outer_femur.stl"/>
</geometry>
</collision>
<visual>
<origin xyz="-3.1682813117653200751e-16 -4.5141273366613611193e-15 -0.032900000000045295789" rpy="-1.5707963267948623631 -1.3877787807679192748e-15 -7.7549078270067512515e-14" />
<geometry>
<mesh filename="package:///bearing_cover_2.stl"/>
</geometry>
<material name="bearing_cover_2_material">
<color rgba="0.26274509803921569651 0.28235294117647058432 0.30196078431372547213 1.0"/>
</material>
</visual>
<collision>
<origin xyz="-3.1682813117653200751e-16 -4.5141273366613611193e-15 -0.032900000000045295789" rpy="-1.5707963267948623631 -1.3877787807679192748e-15 -7.7549078270067512515e-14" />
<geometry>
<mesh filename="package:///bearing_cover_2.stl"/>
</geometry>
</collision>
<visual>
<origin xyz="-6.4989503856405293723e-16 -4.7361719415863419403e-15 -0.032900000000045240278" rpy="-1.5707963267948779063 2.1649348980325810629e-15 -7.7937656328685812433e-14" />
<geometry>
<mesh filename="package:///outer_hip.stl"/>
</geometry>
<material name="outer_hip_material">
<color rgba="0.26274509803921569651 0.28235294117647058432 0.30196078431372547213 1.0"/>
</material>
</visual>
<collision>
<origin xyz="-6.4989503856405293723e-16 -4.7361719415863419403e-15 -0.032900000000045240278" rpy="-1.5707963267948779063 2.1649348980325810629e-15 -7.7937656328685812433e-14" />
<geometry>
<mesh filename="package:///outer_hip.stl"/>
</geometry>
</collision>
<visual>
<origin xyz="3.3323121855078299054e-15 -0.080000000000102614028 0.018300000000037931758" rpy="1.5707963267949058839 -1.0957901253052082297e-13 3.1415926535896701033" />
<geometry>
<mesh filename="package:///rmd_x6.stl"/>
</geometry>
<material name="rmd_x6_material">
<color rgba="0.30196078431372547213 0.30196078431372547213 0.30196078431372547213 1.0"/>
</material>
</visual>
<collision>
<origin xyz="3.3323121855078299054e-15 -0.080000000000102614028 0.018300000000037931758" rpy="1.5707963267949058839 -1.0957901253052082297e-13 3.1415926535896701033" />
<geometry>
<mesh filename="package:///rmd_x6.stl"/>
</geometry>
</collision>
<inertial>
<origin xyz="8.4888659532422210585e-05 -0.047758454799153311765 -0.0053909888545249761566" rpy="0 0 0"/>
<mass value="0.86687774720833488118" />
<inertia ixx="0.003926243304113353691" ixy="-5.7053166963819621322e-07"  ixz="-1.0510332224563595377e-06" iyy="0.0018847416585677544739" iyz="0.001290799139120474932" izz="0.0025605707195885669784" />
</inertial>
</link>

<link name="motor_pulley_2">
<visual>
<origin xyz="0 0 -0.019400000000000021394" rpy="-1.570796326794896558 -1.570796326794896558 0" />
<geometry>
<mesh filename="package:///motor_pulley.stl"/>
</geometry>
<material name="motor_pulley_material">
<color rgba="0.69019607843137253944 0.69019607843137253944 0.69019607843137253944 1.0"/>
</material>
</visual>
<collision>
<origin xyz="0 0 -0.019400000000000021394" rpy="-1.570796326794896558 -1.570796326794896558 0" />
<geometry>
<mesh filename="package:///motor_pulley.stl"/>
</geometry>
</collision>
<inertial>
<origin xyz="-5.9798529235716829197e-16 4.6478062022564490966e-05 -0.010286242910584404014" rpy="0 0 0"/>
<mass value="0.068767168773007744664" />
<inertia ixx="9.6751984178823946693e-06" ixy="-1.2361387073992445573e-20"  ixz="-1.8609909421218016629e-20" iyy="9.6433853220653915591e-06" iyz="-2.7667478259048505499e-08" izz="1.5466315743353802785e-05" />
</inertial>
</link>

<joint name="left_knee_1" type="revolute">
<origin xyz="-6.4989503856405845926e-16 -4.7361719415863419403e-15 -0.032900000000045240278" rpy="-3.1415926535897735761 -2.1496217883359487372e-16 0.027203981649072464521" />
<parent link="left_femur" />
<child link="motor_pulley_2" />
<axis xyz="0 0 1"/>
<limit effort="1" velocity="20" />
<joint_properties friction="0.0"/>
</joint>

<link name="left_tibia">
<visual>
<origin xyz="5.5511151231257235376e-17 0.1500000000000000222 -0.079399903678899902415" rpy="-1.570796326794896558 -7.037070207032461436e-30 2.1004391839447460137e-30" />
<geometry>
<mesh filename="package:///inner_tibia.stl"/>
</geometry>
<material name="inner_tibia_material">
<color rgba="0.91764705882352937127 0.91764705882352937127 0.91764705882352937127 1.0"/>
</material>
</visual>
<collision>
<origin xyz="5.5511151231257235376e-17 0.1500000000000000222 -0.079399903678899902415" rpy="-1.570796326794896558 -7.037070207032461436e-30 2.1004391839447460137e-30" />
<geometry>
<mesh filename="package:///inner_tibia.stl"/>
</geometry>
</collision>
<visual>
<origin xyz="-9.436895709473835251e-16 0.1500000000002120748 -0.079399903678989261491" rpy="-1.5707963267949733854 6.9444450190277565992e-14 5.7714943935138873826e-13" />
<geometry>
<mesh filename="package:///outer_knee_1.stl"/>
</geometry>
<material name="outer_knee_1_material">
<color rgba="0.26274509803921569651 0.28235294117647058432 0.30196078431372547213 1.0"/>
</material>
</visual>
<collision>
<origin xyz="-9.436895709473835251e-16 0.1500000000002120748 -0.079399903678989261491" rpy="-1.5707963267949733854 6.9444450190277565992e-14 5.7714943935138873826e-13" />
<geometry>
<mesh filename="package:///outer_knee_1.stl"/>
</geometry>
</collision>
<visual>
<origin xyz="2.9197089104764038157e-15 2.2315482794965646463e-14 -0.060299903678920983852" rpy="-1.5707963267947344654 1.5707963267943445551 0" />
<geometry>
<mesh filename="package:///outer_knee_pulley.stl"/>
</geometry>
<material name="outer_knee_pulley_material">
<color rgba="0.69019607843137253944 0.69019607843137253944 0.69019607843137253944 1.0"/>
</material>
</visual>
<collision>
<origin xyz="2.9197089104764038157e-15 2.2315482794965646463e-14 -0.060299903678920983852" rpy="-1.5707963267947344654 1.5707963267943445551 0" />
<geometry>
<mesh filename="package:///outer_knee_pulley.stl"/>
</geometry>
</collision>
<visual>
<origin xyz="-8.6042284410046838558e-16 0.15000000000021188051 -0.079399903678988956179" rpy="-1.5707963267949731634 6.7612582199646146052e-14 5.7576167412313404475e-13" />
<geometry>
<mesh filename="package:///outer_knee_2.stl"/>
</geometry>
<material name="outer_knee_2_material">
<color rgba="0.26274509803921569651 0.28235294117647058432 0.30196078431372547213 1.0"/>
</material>
</visual>
<collision>
<origin xyz="-8.6042284410046838558e-16 0.15000000000021188051 -0.079399903678988956179" rpy="-1.5707963267949731634 6.7612582199646146052e-14 5.7576167412313404475e-13" />
<geometry>
<mesh filename="package:///outer_knee_2.stl"/>
</geometry>
</collision>
<visual>
<origin xyz="-1.42941214422076073e-15 0.15000000000020943802 -0.079399903678989344757" rpy="-1.5707963267949740516 6.8611782921811437511e-14 5.1425531855890057436e-13" />
<geometry>
<mesh filename="package:///outer_tibia.stl"/>
</geometry>
<material name="outer_tibia_material">
<color rgba="0.91764705882352937127 0.91764705882352937127 0.91764705882352937127 1.0"/>
</material>
</visual>
<collision>
<origin xyz="-1.42941214422076073e-15 0.15000000000020943802 -0.079399903678989344757" rpy="-1.5707963267949740516 6.8611782921811437511e-14 5.1425531855890057436e-13" />
<geometry>
<mesh filename="package:///outer_tibia.stl"/>
</geometry>
</collision>
<inertial>
<origin xyz="0.0002628842168017034471 -0.056971975798543440794 -0.035984535962881189497" rpy="0 0 0"/>
<mass value="0.13716146838378595607" />
<inertia ixx="0.0006465230949894608262" ixy="-1.717832675107185812e-06"  ixz="1.1854749387355319183e-06" iyy="0.0001073375507647876103" iyz="7.360300797661663405e-05" izz="0.00055827878849027366692" />
</inertial>
</link>

<link name="left_shaft_connector">
<visual>
<origin xyz="-0.1500000000000592526 2.6707126977413776631e-14 -0.024600000000032023334" rpy="-1.5707963267948521491 -7.5552377561769328305e-15 1.5707963267948978903" />
<geometry>
<mesh filename="package:///asc_2_mirror.stl"/>
</geometry>
<material name="asc_2_mirror_material">
<color rgba="0.26274509803921569651 0.28235294117647058432 0.30196078431372547213 1.0"/>
</material>
</visual>
<collision>
<origin xyz="-0.1500000000000592526 2.6707126977413776631e-14 -0.024600000000032023334" rpy="-1.5707963267948521491 -7.5552377561769328305e-15 1.5707963267948978903" />
<geometry>
<mesh filename="package:///asc_2_mirror.stl"/>
</geometry>
</collision>
<visual>
<origin xyz="-0.14999999999999344413 5.5012803434132790848e-14 -0.085199903678963878617" rpy="-1.5707963267948601427 -6.3339924291593051735e-15 1.5707963267944895502" />
<geometry>
<mesh filename="package:///asc_middle.stl"/>
</geometry>
<material name="asc_middle_material">
<color rgba="0.26274509803921569651 0.28235294117647058432 0.30196078431372547213 1.0"/>
</material>
</visual>
<collision>
<origin xyz="-0.14999999999999344413 5.5012803434132790848e-14 -0.085199903678963878617" rpy="-1.5707963267948601427 -6.3339924291593051735e-15 1.5707963267944895502" />
<geometry>
<mesh filename="package:///asc_middle.stl"/>
</geometry>
</collision>
<visual>
<origin xyz="1.6597834218146090279e-14 9.3019451888716302558e-14 -0.0015000000000145140289" rpy="1.5707963267950615371 1.570796326794657416 0" />
<geometry>
<mesh filename="package:///inner_knee_pulley.stl"/>
</geometry>
<material name="inner_knee_pulley_material">
<color rgba="0.69019607843137253944 0.69019607843137253944 0.69019607843137253944 1.0"/>
</material>
</visual>
<collision>
<origin xyz="1.6597834218146090279e-14 9.3019451888716302558e-14 -0.0015000000000145140289" rpy="1.5707963267950615371 1.570796326794657416 0" />
<geometry>
<mesh filename="package:///inner_knee_pulley.stl"/>
</geometry>
</collision>
<visual>
<origin xyz="-0.14999999999999436007 5.4429936346211853806e-14 -0.085199903678963573306" rpy="-1.5707963267948594765 -4.4466132872963031854e-15 1.5707963267944911046" />
<geometry>
<mesh filename="package:///asc_alu.stl"/>
</geometry>
<material name="asc_alu_material">
<color rgba="0.91764705882352937127 0.91764705882352937127 0.91764705882352937127 1.0"/>
</material>
</visual>
<collision>
<origin xyz="-0.14999999999999436007 5.4429936346211853806e-14 -0.085199903678963573306" rpy="-1.5707963267948594765 -4.4466132872963031854e-15 1.5707963267944911046" />
<geometry>
<mesh filename="package:///asc_alu.stl"/>
</geometry>
</collision>
<visual>
<origin xyz="-0.14999999999999258371 5.5289266406812643657e-14 -0.075200000000050795657" rpy="-1.5707963267948610309 -5.1127471020718712151e-15 1.570796326794488218" />
<geometry>
<mesh filename="package:///asc_alu.stl"/>
</geometry>
<material name="asc_alu_material">
<color rgba="0.91764705882352937127 0.91764705882352937127 0.91764705882352937127 1.0"/>
</material>
</visual>
<collision>
<origin xyz="-0.14999999999999258371 5.5289266406812643657e-14 -0.075200000000050795657" rpy="-1.5707963267948610309 -5.1127471020718712151e-15 1.570796326794488218" />
<geometry>
<mesh filename="package:///asc_alu.stl"/>
</geometry>
</collision>
<inertial>
<origin xyz="-0.00044561009876444181285 -0.0016766488738696027488 -0.026351195328629815201" rpy="0 0 0"/>
<mass value="0.061135779919446485431" />
<inertia ixx="1.9470862636153506712e-05" ixy="-5.9427237208904890664e-07"  ixz="-1.2089964867282510798e-07" iyy="1.5010214411515764032e-05" iyz="-6.5806154730471581919e-08" izz="1.2964537959518320081e-05" />
</inertial>
</link>

<link name="ankle_shaft">
<visual>
<origin xyz="-0.29999999999999937828 -0.024999999999998450545 -0.06139999999999232877" rpy="-1.5707963267948976682 -6.1634183000248090682e-16 1.570796326794891673" />
<geometry>
<mesh filename="package:///shaft_end.stl"/>
</geometry>
<material name="shaft_end_material">
<color rgba="0.91764705882352937127 0.91764705882352937127 0.91764705882352937127 1.0"/>
</material>
</visual>
<collision>
<origin xyz="-0.29999999999999937828 -0.024999999999998450545 -0.06139999999999232877" rpy="-1.5707963267948976682 -6.1634183000248090682e-16 1.570796326794891673" />
<geometry>
<mesh filename="package:///shaft_end.stl"/>
</geometry>
</collision>
<visual>
<origin xyz="0.15000000000000018874 -0.02499999999999502967 -0.061399999999994937794" rpy="-1.5707963267948938935 -2.6033049414055136891e-15 -1.5707963267948756858" />
<geometry>
<mesh filename="package:///shaft_end.stl"/>
</geometry>
<material name="shaft_end_material">
<color rgba="0.91764705882352937127 0.91764705882352937127 0.91764705882352937127 1.0"/>
</material>
</visual>
<collision>
<origin xyz="0.15000000000000018874 -0.02499999999999502967 -0.061399999999994937794" rpy="-1.5707963267948938935 -2.6033049414055136891e-15 -1.5707963267948756858" />
<geometry>
<mesh filename="package:///shaft_end.stl"/>
</geometry>
</collision>
<visual>
<origin xyz="0.14999999999999838463 -0.024999999999995487637 -0.061399999999994937794" rpy="-1.570796326794891673 2.6702544255589082911e-15 -1.5707963267948901187" />
<geometry>
<mesh filename="package:///ankle_shaft.stl"/>
</geometry>
<material name="ankle_shaft_material">
<color rgba="0.49803921568627451677 0.49803921568627451677 0.49803921568627451677 1.0"/>
</material>
</visual>
<collision>
<origin xyz="0.14999999999999838463 -0.024999999999995487637 -0.061399999999994937794" rpy="-1.570796326794891673 2.6702544255589082911e-15 -1.5707963267948901187" />
<geometry>
<mesh filename="package:///ankle_shaft.stl"/>
</geometry>
</collision>
<inertial>
<origin xyz="-0.074999971953935179458 -0.025000034945364159322 -0.003499991903622612973" rpy="0 0 0"/>
<mass value="0.027812191526678471665" />
<inertia ixx="7.4552320334518487176e-06" ixy="-2.153239892785321788e-05"  ixz="-1.983763617479444813e-12" iyy="6.3940111974529801361e-05" iyz="-1.6799617058741562899e-12" izz="7.1297798653936989097e-05" />
</inertial>
</link>

<link name="closing_left_1">
<inertial>
<origin xyz="0 0 0" rpy="0 0 0" />
<mass value="1e-9" />
<inertia ixx="0" ixy="0" ixz="0" iyy="0" iyz="0" izz="0" />
</inertial>
</link>
<joint name="closing_left_1_frame" type="fixed">
<origin xyz="-0.14999999999999771849 -0.050000000000000030531 -6.4531713306337223912e-16" rpy="-9.9920072216398766916e-16 -1.8870233948204239244e-15 -6.3481963726237970789e-15" />
<parent link="ankle_shaft" />
<child link="closing_left_1" />
<axis xyz="0 0 0"/>
</joint>

<joint name="left_ankle_pitch_3" type="revolute">
<origin xyz="-8.8817841970012523234e-16 -0.025000000000006249862 -0.023800000000064245459" rpy="-1.0941417982723899411e-14 -2.9892138505736365462e-14 3.1415926535816263154" />
<parent link="left_shaft_connector" />
<child link="ankle_shaft" />
<axis xyz="0 0 1"/>
<limit effort="1" velocity="20" />
<joint_properties friction="0.0"/>
</joint>

<joint name="left_ankle_pitch_2" type="revolute">
<origin xyz="3.5319520210675786405e-15 2.5812685322534889565e-14 -0.048799903678906839111" rpy="3.1415926535896776528 -1.2602542893967900286e-13 -1.5707963268030824544" />
<parent link="left_tibia" />
<child link="left_shaft_connector" />
<axis xyz="0 0 1"/>
<limit effort="1" velocity="20" lower="-1.2375158973761830605" upper="1.570796326794896558"/>
<joint_properties friction="0.0"/>
</joint>

<link name="left_ankle">
<visual>
<origin xyz="-1.9081958235740144873e-17 0.30000000000000004441 -0.024600000000000021155" rpy="-1.570796326794896558 2.6827445059424906099e-30 1.1077643045679550087e-29" />
<geometry>
<mesh filename="package:///ankle_mirror.stl"/>
</geometry>
<material name="ankle_mirror_material">
<color rgba="0.26274509803921569651 0.28235294117647058432 0.30196078431372547213 1.0"/>
</material>
</visual>
<collision>
<origin xyz="-1.9081958235740144873e-17 0.30000000000000004441 -0.024600000000000021155" rpy="-1.570796326794896558 2.6827445059424906099e-30 1.1077643045679550087e-29" />
<geometry>
<mesh filename="package:///ankle_mirror.stl"/>
</geometry>
</collision>
<visual>
<origin xyz="-2.8275992658419904601e-16 0.30000000000000043299 -0.024600000000000125239" rpy="-1.570796326794896558 2.6827445059424906099e-30 1.1077643045679550087e-29" />
<geometry>
<mesh filename="package:///upper_foot_mirror.stl"/>
</geometry>
<material name="upper_foot_mirror_material">
<color rgba="0.26274509803921569651 0.28235294117647058432 0.30196078431372547213 1.0"/>
</material>
</visual>
<collision>
<origin xyz="-2.8275992658419904601e-16 0.30000000000000043299 -0.024600000000000125239" rpy="-1.570796326794896558 2.6827445059424906099e-30 1.1077643045679550087e-29" />
<geometry>
<mesh filename="package:///upper_foot_mirror.stl"/>
</geometry>
</collision>
<visual>
<origin xyz="-1.9480932055860975048e-15 0.30000000000000159872 -0.085199999999998471401" rpy="-1.5707963267948958919 1.6653345369377784445e-16 6.106226635439406213e-16" />
<geometry>
<mesh filename="package:///ankle_alu.stl"/>
</geometry>
<material name="ankle_alu_material">
<color rgba="0.91764705882352937127 0.91764705882352937127 0.91764705882352937127 1.0"/>
</material>
</visual>
<collision>
<origin xyz="-1.9480932055860975048e-15 0.30000000000000159872 -0.085199999999998471401" rpy="-1.5707963267948958919 1.6653345369377784445e-16 6.106226635439406213e-16" />
<geometry>
<mesh filename="package:///ankle_alu.stl"/>
</geometry>
</collision>
<visual>
<origin xyz="-1.3896384074218050762e-15 0.30000000000000104361 -0.075199999999995909006" rpy="-1.5707963267948956698 -1.1102230246238779695e-16 7.771561172376873797e-16" />
<geometry>
<mesh filename="package:///ankle_alu.stl"/>
</geometry>
<material name="ankle_alu_material">
<color rgba="0.91764705882352937127 0.91764705882352937127 0.91764705882352937127 1.0"/>
</material>
</visual>
<collision>
<origin xyz="-1.3896384074218050762e-15 0.30000000000000104361 -0.075199999999995909006" rpy="-1.5707963267948956698 -1.1102230246238779695e-16 7.771561172376873797e-16" />
<geometry>
<mesh filename="package:///ankle_alu.stl"/>
</geometry>
</collision>
<inertial>
<origin xyz="0.019071753914173084771 -0.015227960231764594082 -0.026661923613647268982" rpy="0 0 0"/>
<mass value="0.03015568460546654006" />
<inertia ixx="6.4522369932970303894e-06" ixy="3.363416570264715613e-07"  ixz="2.6974763448302380416e-07" iyy="9.3388995199645648195e-06" iyz="-2.1899017204691733305e-07" izz="1.1938920640138241352e-05" />
</inertial>
</link>

<link name="closing_left_2">
<inertial>
<origin xyz="0 0 0" rpy="0 0 0" />
<mass value="1e-9" />
<inertia ixx="0" ixy="0" ixz="0" iyy="0" iyz="0" izz="0" />
</inertial>
</link>
<joint name="closing_left_2_frame" type="fixed">
<origin xyz="0.024999999999998648303 4.9960036108132044319e-16 -0.023800000000004244843" rpy="-7.5065461826747186547e-16 1.3561226421362389337e-16 -3.1415926535897926719" />
<parent link="left_ankle" />
<child link="closing_left_2" />
<axis xyz="0 0 0"/>
</joint>

<link name="left_foot">
<visual>
<origin xyz="0.057900000000035659053 0.33249999999995805133 0.0064999999999909990889" rpy="-1.5707963267949427433 -1.5707963267948410468 0" />
<geometry>
<mesh filename="package:///foot_alu.stl"/>
</geometry>
<material name="foot_alu_material">
<color rgba="0.91764705882352937127 0.91764705882352937127 0.91764705882352937127 1.0"/>
</material>
</visual>
<collision>
<origin xyz="0.057900000000035659053 0.33249999999995805133 0.0064999999999909990889" rpy="-1.5707963267949427433 -1.5707963267948410468 0" />
<geometry>
<mesh filename="package:///foot_alu.stl"/>
</geometry>
</collision>
<visual>
<origin xyz="-0.0026999999999919449545 0.33250000000000001776 0.0065000000000000075079" rpy="-1.570796326794896558 -1.570796326794896558 0" />
<geometry>
<mesh filename="package:///lower_foot_mirror.stl"/>
</geometry>
<material name="lower_foot_mirror_material">
<color rgba="0.26274509803921569651 0.28235294117647058432 0.30196078431372547213 1.0"/>
</material>
</visual>
<collision>
<origin xyz="-0.0026999999999919449545 0.33250000000000001776 0.0065000000000000075079" rpy="-1.570796326794896558 -1.570796326794896558 0" />
<geometry>
<mesh filename="package:///lower_foot_mirror.stl"/>
</geometry>
</collision>
<inertial>
<origin xyz="-7.274456779830905525e-05 -0.015405356144901849458 0.0046860616625106028474" rpy="0 0 0"/>
<mass value="0.055361091085330056683" />
<inertia ixx="6.8711126907465479795e-05" ixy="5.2824061287842230133e-08"  ixz="8.3304804796566400886e-08" iyy="8.3573527857425623983e-05" iyz="-2.3992747304827991142e-06" izz="1.7621203254803429492e-05" />
</inertial>
</link>

<link name="left">
<inertial>
<origin xyz="0 0 0" rpy="0 0 0" />
<mass value="1e-9" />
<inertia ixx="0" ixy="0" ixz="0" iyy="0" iyz="0" izz="0" />
</inertial>
</link>
<joint name="left_frame" type="fixed">
<origin xyz="2.7956803538842223134e-14 -0.018500000000039928949 -0.00075698915672654798481" rpy="-1.5707963267948510389 1.5707963267948410468 0" />
<parent link="left_foot" />
<child link="left" />
<axis xyz="0 0 0"/>
</joint>

<joint name="left_ankle_roll" type="revolute">
<origin xyz="-0.0065000000000031482247 -0.032500000000081408214 -0.027299999999997218852" rpy="6.804680578063719959e-27 1.570796326794891673 0" />
<parent link="left_ankle" />
<child link="left_foot" />
<axis xyz="0 0 1"/>
<limit effort="1" velocity="20" lower="-0.1745329251994329478" upper="0.52359877559829881566"/>
<joint_properties friction="0.0"/>
</joint>

<joint name="left_ankle_pitch_4" type="revolute">
<origin xyz="7.4904621468630412097e-15 -0.15000000000016919244 -0.048799903678869403778" rpy="-3.1415926535896323557 -1.077999630545015724e-13 -3.1415926535897318317" />
<parent link="left_tibia" />
<child link="left_ankle" />
<axis xyz="0 0 1"/>
<limit effort="1" velocity="20" lower="-1.2375158973761830605" upper="1.570796326794896558"/>
<joint_properties friction="0.0"/>
</joint>

<joint name="left_knee_2" type="revolute">
<origin xyz="9.2534826152769928882e-15 -0.15000000000019156343 0.046499903679005291646" rpy="2.7514247754725331809e-15 8.3266726844769289951e-16 -2.997079401201851963e-16" />
<parent link="left_femur" />
<child link="left_tibia" />
<axis xyz="0 0 1"/>
<limit effort="1" velocity="20" lower="-2.356194490192344837" upper="0"/>
<joint_properties friction="0.0"/>
</joint>

<link name="motor_pulley_3">
<visual>
<origin xyz="-4.336808689942017736e-19 1.3877787807814456755e-17 -0.019400000000000021394" rpy="-1.570796326794896558 -1.570796326794896558 0" />
<geometry>
<mesh filename="package:///motor_pulley.stl"/>
</geometry>
<material name="motor_pulley_material">
<color rgba="0.69019607843137253944 0.69019607843137253944 0.69019607843137253944 1.0"/>
</material>
</visual>
<collision>
<origin xyz="-4.336808689942017736e-19 1.3877787807814456755e-17 -0.019400000000000021394" rpy="-1.570796326794896558 -1.570796326794896558 0" />
<geometry>
<mesh filename="package:///motor_pulley.stl"/>
</geometry>
</collision>
<inertial>
<origin xyz="-6.247386921882587459e-16 4.6478062022551466987e-05 -0.010286242910584412688" rpy="0 0 0"/>
<mass value="0.068767168773007730787" />
<inertia ixx="9.6751984178823845049e-06" ixy="-4.1564791805023949378e-21"  ixz="-1.0223952371155422061e-20" iyy="9.6433853220654017235e-06" iyz="-2.7667478259048359915e-08" izz="1.5466315743353802785e-05" />
</inertial>
</link>

<joint name="left_ankle_pitch_1" type="revolute">
<origin xyz="3.3323121855078318776e-15 -0.080000000000102614028 0.018300000000037931758" rpy="1.215759610759047731e-14 -1.1177312336507953765e-13 3.0929397216733969245" />
<parent link="left_femur" />
<child link="motor_pulley_3" />
<axis xyz="0 0 1"/>
<limit effort="1" velocity="20" />
<joint_properties friction="0.0"/>
</joint>

<joint name="left_hip_pitch" type="revolute">
<origin xyz="0.028499903678899887738 0.057999998778099942642 -0.026999998778100064295" rpy="3.141592653589793116 1.5707963267948190644 0" />
<parent link="left_lower_hip" />
<child link="left_femur" />
<axis xyz="0 0 1"/>
<limit effort="1" velocity="20" lower="-1.0471975511965976313" upper="1.9198621771937625091"/>
<joint_properties friction="0.0"/>
</joint>

<joint name="left_hip_roll_2" type="revolute">
<origin xyz="-0.036349989645404076621 -2.9155150516047001474e-13 0.12149999999995617084" rpy="1.5707963267948956698 -1.871157079710716612e-14 -1.570796326794792197" />
<parent link="left_upper_hip" />
<child link="left_lower_hip" />
<axis xyz="0 0 1"/>
<limit effort="1" velocity="20" lower="-1.0471975511965976313" upper="0.1745329251994329478"/>
<joint_properties friction="0.0"/>
</joint>

<joint name="left_hip_yaw" type="revolute">
<origin xyz="0.0093499908672946222682 -0.061399903678804698681 0.17949999877806774307" rpy="3.1415926535895537519 4.2659356562086370119e-16 3.7448197579691025492e-14" />
<parent link="pelvis" />
<child link="left_upper_hip" />
<axis xyz="0 0 1"/>
<limit effort="1" velocity="20" lower="-1.570796326794896558" upper="1.570796326794896558"/>
<joint_properties friction="0.0"/>
</joint>

<link name="right_upper_hip">
<visual>
<origin xyz="-0.0093499908672999374609 -0.061399903678899914183 0.1794999987781000228" rpy="3.141592653589793116 3.912916525759393916e-16 -8.7374878414715324848e-31" />
<geometry>
<mesh filename="package:///upper_hip_5.stl"/>
</geometry>
<material name="upper_hip_5_material">
<color rgba="0.26274509803921569651 0.28235294117647058432 0.30196078431372547213 1.0"/>
</material>
</visual>
<collision>
<origin xyz="-0.0093499908672999374609 -0.061399903678899914183 0.1794999987781000228" rpy="3.141592653589793116 3.912916525759393916e-16 -8.7374878414715324848e-31" />
<geometry>
<mesh filename="package:///upper_hip_5.stl"/>
</geometry>
</collision>
<visual>
<origin xyz="0.037849979155005354647 -0.10606601717797919937 0.22756601717797894646" rpy="-7.664774588712629555e-16 0.78539816339744850104 -1.57079632679489678" />
<geometry>
<mesh filename="package:///bearing_cover_1.stl"/>
</geometry>
<material name="bearing_cover_1_material">
<color rgba="0.26274509803921569651 0.28235294117647058432 0.30196078431372547213 1.0"/>
</material>
</visual>
<collision>
<origin xyz="0.037849979155005354647 -0.10606601717797919937 0.22756601717797894646" rpy="-7.664774588712629555e-16 0.78539816339744850104 -1.57079632679489678" />
<geometry>
<mesh filename="package:///bearing_cover_1.stl"/>
</geometry>
</collision>
<visual>
<origin xyz="0.011249993324321095819 4.7462034302725442103e-15 0.066499999999996894928" rpy="3.1415926535897926719 8.1306824955106829839e-18 -1.570796326794896336" />
<geometry>
<mesh filename="package:///rmd_x6.stl"/>
</geometry>
<material name="rmd_x6_material">
<color rgba="0.30196078431372547213 0.30196078431372547213 0.30196078431372547213 1.0"/>
</material>
</visual>
<collision>
<origin xyz="0.011249993324321095819 4.7462034302725442103e-15 0.066499999999996894928" rpy="3.1415926535897926719 8.1306824955106829839e-18 -1.570796326794896336" />
<geometry>
<mesh filename="package:///rmd_x6.stl"/>
</geometry>
</collision>
<visual>
<origin xyz="0.066349988423513264757 -0.061399903678896944337 0.17949999877809680315" rpy="-3.141592653589793116 4.3920284281833140618e-16 3.21319516041969985e-16" />
<geometry>
<mesh filename="package:///upper_hip_2.stl"/>
</geometry>
<material name="upper_hip_2_material">
<color rgba="0.91764705882352937127 0.91764705882352937127 0.91764705882352937127 1.0"/>
</material>
</visual>
<collision>
<origin xyz="0.066349988423513264757 -0.061399903678896944337 0.17949999877809680315" rpy="-3.141592653589793116 4.3920284281833140618e-16 3.21319516041969985e-16" />
<geometry>
<mesh filename="package:///upper_hip_2.stl"/>
</geometry>
</collision>
<visual>
<origin xyz="-0.041849811576486754816 -0.061399903678896972092 0.17949999877809688642" rpy="-3.141592653589793116 7.8686673162553102313e-16 3.213195160419907912e-16" />
<geometry>
<mesh filename="package:///upper_hip_1.stl"/>
</geometry>
<material name="upper_hip_1_material">
<color rgba="0.91764705882352937127 0.91764705882352937127 0.91764705882352937127 1.0"/>
</material>
</visual>
<collision>
<origin xyz="-0.041849811576486754816 -0.061399903678896972092 0.17949999877809688642" rpy="-3.141592653589793116 7.8686673162553102313e-16 3.213195160419907912e-16" />
<geometry>
<mesh filename="package:///upper_hip_1.stl"/>
</geometry>
</collision>
<visual>
<origin xyz="-0.016249899864178983522 0.10606601717798688767 0.015433982822014774561" rpy="3.1415926535897922278 0.78539816339744916718 -1.5707963267948970021" />
<geometry>
<mesh filename="package:///bearing_cover_1.stl"/>
</geometry>
<material name="bearing_cover_1_material">
<color rgba="0.26274509803921569651 0.28235294117647058432 0.30196078431372547213 1.0"/>
</material>
</visual>
<collision>
<origin xyz="-0.016249899864178983522 0.10606601717798688767 0.015433982822014774561" rpy="3.1415926535897922278 0.78539816339744916718 -1.5707963267948970021" />
<geometry>
<mesh filename="package:///bearing_cover_1.stl"/>
</geometry>
</collision>
<visual>
<origin xyz="0.0093499908673085520977 -0.061399903678897443937 0.17949999877809688642" rpy="3.141592653589793116 -5.137563324907244352e-16 -3.141592653589793116" />
<geometry>
<mesh filename="package:///upper_hip_4_mirror.stl"/>
</geometry>
<material name="upper_hip_4_mirror_material">
<color rgba="0.26274509803921569651 0.28235294117647058432 0.30196078431372547213 1.0"/>
</material>
</visual>
<collision>
<origin xyz="0.0093499908673085520977 -0.061399903678897443937 0.17949999877809688642" rpy="3.141592653589793116 -5.137563324907244352e-16 -3.141592653589793116" />
<geometry>
<mesh filename="package:///upper_hip_4_mirror.stl"/>
</geometry>
</collision>
<visual>
<origin xyz="0.0093499908673085382199 -0.061399903678897443937 0.17949999877809691418" rpy="3.141592653589793116 -7.8686673162553102313e-16 -3.141592653589793116" />
<geometry>
<mesh filename="package:///upper_hip_3_mirror.stl"/>
</geometry>
<material name="upper_hip_3_mirror_material">
<color rgba="0.26274509803921569651 0.28235294117647058432 0.30196078431372547213 1.0"/>
</material>
</visual>
<collision>
<origin xyz="0.0093499908673085382199 -0.061399903678897443937 0.17949999877809691418" rpy="3.141592653589793116 -7.8686673162553102313e-16 -3.141592653589793116" />
<geometry>
<mesh filename="package:///upper_hip_3_mirror.stl"/>
</geometry>
</collision>
<inertial>
<origin xyz="-0.0023702487193062700757 0.00027244056287595947927 0.071906001353989071334" rpy="0 0 0"/>
<mass value="0.47353718531678168358" />
<inertia ixx="0.00053695798658939569888" ixy="-1.6441131527699454534e-06"  ixz="-4.7498644415459584237e-05" iyy="0.00053238425050721100741" iyz="-4.5986112122242730609e-06" izz="0.00029813456676859849967" />
</inertial>
</link>

<link name="motor_pulley_4">
<visual>
<origin xyz="-1.0408340855860842566e-17 0 -0.019400000000000021394" rpy="-1.570796326794896558 -1.570796326794896558 0" />
<geometry>
<mesh filename="package:///motor_pulley.stl"/>
</geometry>
<material name="motor_pulley_material">
<color rgba="0.69019607843137253944 0.69019607843137253944 0.69019607843137253944 1.0"/>
</material>
</visual>
<collision>
<origin xyz="-1.0408340855860842566e-17 0 -0.019400000000000021394" rpy="-1.570796326794896558 -1.570796326794896558 0" />
<geometry>
<mesh filename="package:///motor_pulley.stl"/>
</geometry>
</collision>
<inertial>
<origin xyz="-6.1553739434809936499e-16 4.6478062022540265823e-05 -0.01028624291058439881" rpy="0 0 0"/>
<mass value="0.068767168773007744664" />
<inertia ixx="9.6751984178822218746e-06" ixy="-6.896473249101844774e-21"  ixz="-1.3220795987866151869e-20" iyy="9.6433853220652407872e-06" iyz="-2.766747825904122631e-08" izz="1.5466315743353470748e-05" />
</inertial>
</link>

<joint name="right_hip_roll_1" type="revolute">
<origin xyz="0.011249993324321095819 4.7184478546569152968e-15 0.066499999999996894928" rpy="1.5707963267948947816 -1.1323782996484244023 -1.5707963267948938935" />
<parent link="right_upper_hip" />
<child link="motor_pulley_4" />
<axis xyz="0 0 1"/>
<limit effort="1" velocity="20" />
<joint_properties friction="0.0"/>
</joint>

<link name="right_lower_hip">
<visual>
<origin xyz="-0.061399903678899886428 0.057999998778099991215 -0.026999998778099998376" rpy="1.570796326794896558 1.570796326794896558 0" />
<geometry>
<mesh filename="package:///inner_hip_mirror.stl"/>
</geometry>
<material name="inner_hip_mirror_material">
<color rgba="0.26274509803921569651 0.28235294117647058432 0.30196078431372547213 1.0"/>
</material>
</visual>
<collision>
<origin xyz="-0.061399903678899886428 0.057999998778099991215 -0.026999998778099998376" rpy="1.570796326794896558 1.570796326794896558 0" />
<geometry>
<mesh filename="package:///inner_hip_mirror.stl"/>
</geometry>
</collision>
<visual>
<origin xyz="0.018000000000009869217 0.057999998778100012031 -0.026999998778099987967" rpy="6.1232339957380602608e-17 0.52359877559829870464 1.570796326794896558" />
<geometry>
<mesh filename="package:///rmd_x6.stl"/>
</geometry>
<material name="rmd_x6_material">
<color rgba="0.30196078431372547213 0.30196078431372547213 0.30196078431372547213 1.0"/>
</material>
</visual>
<collision>
<origin xyz="0.018000000000009869217 0.057999998778100012031 -0.026999998778099987967" rpy="6.1232339957380602608e-17 0.52359877559829870464 1.570796326794896558" />
<geometry>
<mesh filename="package:///rmd_x6.stl"/>
</geometry>
</collision>
<inertial>
<origin xyz="-0.00015924404442528602272 0.053021139103012336624 -0.025932275868626709914" rpy="0 0 0"/>
<mass value="0.38603836162425869682" />
<inertia ixx="0.0003218425071846274391" ixy="-8.1737066701673208081e-07"  ixz="-3.0794810991894749776e-07" iyy="0.00016940355259134978489" iyz="1.4152846896293210739e-05" izz="0.00023859453585934226353" />
</inertial>
</link>

<link name="right_femur">
<visual>
<origin xyz="-4.8130829790237116697e-13 2.4206570587515802921e-13 0.12889980735775616316" rpy="1.5707963267948961139 -4.6054716712117808014e-18 2.396971510165762953e-13" />
<geometry>
<mesh filename="package:///inner_femur.stl"/>
</geometry>
<material name="inner_femur_material">
<color rgba="0.91764705882352937127 0.91764705882352937127 0.91764705882352937127 1.0"/>
</material>
</visual>
<collision>
<origin xyz="-4.8130829790237116697e-13 2.4206570587515802921e-13 0.12889980735775616316" rpy="1.5707963267948961139 -4.6054716712117808014e-18 2.396971510165762953e-13" />
<geometry>
<mesh filename="package:///inner_femur.stl"/>
</geometry>
</collision>
<visual>
<origin xyz="-4.7983578419601808113e-13 2.3065916449899682841e-13 -0.03290002098080624382" rpy="1.5707963267948961139 -4.6054716712117808014e-18 2.396971510165762953e-13" />
<geometry>
<mesh filename="package:///outer_femur.stl"/>
</geometry>
<material name="outer_femur_material">
<color rgba="0.91764705882352937127 0.91764705882352937127 0.91764705882352937127 1.0"/>
</material>
</visual>
<collision>
<origin xyz="-4.7983578419601808113e-13 2.3065916449899682841e-13 -0.03290002098080624382" rpy="1.5707963267948961139 -4.6054716712117808014e-18 2.396971510165762953e-13" />
<geometry>
<mesh filename="package:///outer_femur.stl"/>
</geometry>
</collision>
<visual>
<origin xyz="-1.3617031301288535734e-16 -2.0852227908145500428e-15 -0.03289999999999071445" rpy="-1.5707963267948958919 -1.1796119636642236473e-16 -3.141592653589793116" />
<geometry>
<mesh filename="package:///outer_hip.stl"/>
</geometry>
<material name="outer_hip_material">
<color rgba="0.26274509803921569651 0.28235294117647058432 0.30196078431372547213 1.0"/>
</material>
</visual>
<collision>
<origin xyz="-1.3617031301288535734e-16 -2.0852227908145500428e-15 -0.03289999999999071445" rpy="-1.5707963267948958919 -1.1796119636642236473e-16 -3.141592653589793116" />
<geometry>
<mesh filename="package:///outer_hip.stl"/>
</geometry>
</collision>
<visual>
<origin xyz="-1.3617031301288535734e-16 -2.0852227908145500428e-15 -0.03289999999999071445" rpy="-1.5707963267948958919 -1.1796119636642236473e-16 -3.141592653589793116" />
<geometry>
<mesh filename="package:///rmd_x6.stl"/>
</geometry>
<material name="rmd_x6_material">
<color rgba="0.30196078431372547213 0.30196078431372547213 0.30196078431372547213 1.0"/>
</material>
</visual>
<collision>
<origin xyz="-1.3617031301288535734e-16 -2.0852227908145500428e-15 -0.03289999999999071445" rpy="-1.5707963267948958919 -1.1796119636642236473e-16 -3.141592653589793116" />
<geometry>
<mesh filename="package:///rmd_x6.stl"/>
</geometry>
</collision>
<visual>
<origin xyz="-5.03038493187640053e-13 0.30000000000010984547 -0.032900000000013807089" rpy="-1.570796326794896558 -1.5059401377942495208e-28 -2.5320914478302095742e-31" />
<geometry>
<mesh filename="package:///bearing_cover_2.stl"/>
</geometry>
<material name="bearing_cover_2_material">
<color rgba="0.26274509803921569651 0.28235294117647058432 0.30196078431372547213 1.0"/>
</material>
</visual>
<collision>
<origin xyz="-5.03038493187640053e-13 0.30000000000010984547 -0.032900000000013807089" rpy="-1.570796326794896558 -1.5059401377942495208e-28 -2.5320914478302095742e-31" />
<geometry>
<mesh filename="package:///bearing_cover_2.stl"/>
</geometry>
</collision>
<visual>
<origin xyz="-4.8066224666994531705e-13 2.3650121306515554814e-13 0.047999893188474973549" rpy="1.5707963267948961139 -4.6054716712117808014e-18 2.396971510165762953e-13" />
<geometry>
<mesh filename="package:///bearing_cover_1.stl"/>
</geometry>
<material name="bearing_cover_1_material">
<color rgba="0.26274509803921569651 0.28235294117647058432 0.30196078431372547213 1.0"/>
</material>
</visual>
<collision>
<origin xyz="-4.8066224666994531705e-13 2.3650121306515554814e-13 0.047999893188474973549" rpy="1.5707963267948961139 -4.6054716712117808014e-18 2.396971510165762953e-13" />
<geometry>
<mesh filename="package:///bearing_cover_1.stl"/>
</geometry>
</collision>
<visual>
<origin xyz="-4.8647140664784363295e-13 0.080000000000202492467 0.01829999999997888871" rpy="1.5707963267948961139 -4.6054716712117808014e-18 2.396971510165762953e-13" />
<geometry>
<mesh filename="package:///rmd_x6.stl"/>
</geometry>
<material name="rmd_x6_material">
<color rgba="0.30196078431372547213 0.30196078431372547213 0.30196078431372547213 1.0"/>
</material>
</visual>
<collision>
<origin xyz="-4.8647140664784363295e-13 0.080000000000202492467 0.01829999999997888871" rpy="1.5707963267948961139 -4.6054716712117808014e-18 2.396971510165762953e-13" />
<geometry>
<mesh filename="package:///rmd_x6.stl"/>
</geometry>
</collision>
<inertial>
<origin xyz="8.4913046665807548688e-05 0.04772908212810014067 -0.00539441933055189414" rpy="0 0 0"/>
<mass value="0.86662877599053789179" />
<inertia ixx="0.0039231858807385056043" ixy="5.6837019985673955495e-07"  ixz="-1.0512856579624153065e-06" iyy="0.0018841904459340386071" iyz="-0.001290495092872886258" izz="0.0025578700820780477659" />
</inertial>
</link>

<link name="motor_pulley_5">
<visual>
<origin xyz="-1.2621774483536188887e-29 0 -0.019400000000000000577" rpy="-1.57079632679489678 -1.570796326794896558 0" />
<geometry>
<mesh filename="package:///motor_pulley.stl"/>
</geometry>
<material name="motor_pulley_material">
<color rgba="0.69019607843137253944 0.69019607843137253944 0.69019607843137253944 1.0"/>
</material>
</visual>
<collision>
<origin xyz="-1.2621774483536188887e-29 0 -0.019400000000000000577" rpy="-1.57079632679489678 -1.570796326794896558 0" />
<geometry>
<mesh filename="package:///motor_pulley.stl"/>
</geometry>
</collision>
<inertial>
<origin xyz="-5.7991566180826893119e-16 4.6478062022543254156e-05 -0.010286242910584355442" rpy="0 0 0"/>
<mass value="0.068767168773007744664" />
<inertia ixx="9.6751984178822337331e-06" ixy="-4.0763460586613203818e-21"  ixz="-2.421653961310243821e-20" iyy="9.6433853220652543397e-06" iyz="-2.7667478259047966178e-08" izz="1.5466315743353477525e-05" />
</inertial>
</link>

<joint name="right_knee_1" type="revolute">
<origin xyz="-1.3617031301289482367e-16 -2.0852227908145500428e-15 -0.03289999999999071445" rpy="-3.141592653589793116 1.7432697531983926309e-15 2.0043675289397979711" />
<parent link="right_femur" />
<child link="motor_pulley_5" />
<axis xyz="0 0 1"/>
<limit effort="1" velocity="20" />
<joint_properties friction="0.0"/>
</joint>

<link name="right_tibia">
<visual>
<origin xyz="1.7838624332061113248e-14 -0.14999999999989385713 0.074399903678889031666" rpy="1.5707963267948958919 -3.2968419746824301903e-18 2.6068036618199210732e-13" />
<geometry>
<mesh filename="package:///inner_tibia.stl"/>
</geometry>
<material name="inner_tibia_material">
<color rgba="0.91764705882352937127 0.91764705882352937127 0.91764705882352937127 1.0"/>
</material>
</visual>
<collision>
<origin xyz="1.7838624332061113248e-14 -0.14999999999989385713 0.074399903678889031666" rpy="1.5707963267948958919 -3.2968419746824301903e-18 2.6068036618199210732e-13" />
<geometry>
<mesh filename="package:///inner_tibia.stl"/>
</geometry>
</collision>
<visual>
<origin xyz="1.3280656444554248409e-14 -0.1499999999998991862 -0.079399903678864541812" rpy="1.5707963267948259478 -2.0835712847285112891e-14 2.521316488923770893e-13" />
<geometry>
<mesh filename="package:///outer_knee_1_mirror.stl"/>
</geometry>
<material name="outer_knee_1_mirror_material">
<color rgba="0.26274509803921569651 0.28235294117647058432 0.30196078431372547213 1.0"/>
</material>
</visual>
<collision>
<origin xyz="1.3280656444554248409e-14 -0.1499999999998991862 -0.079399903678864541812" rpy="1.5707963267948259478 -2.0835712847285112891e-14 2.521316488923770893e-13" />
<geometry>
<mesh filename="package:///outer_knee_1_mirror.stl"/>
</geometry>
</collision>
<visual>
<origin xyz="7.951857074682654999e-15 5.0848214527832169551e-14 -0.060299903678891847436" rpy="3.141592653589708295 1.5707963267945217467 0" />
<geometry>
<mesh filename="package:///outer_knee_pulley.stl"/>
</geometry>
<material name="outer_knee_pulley_material">
<color rgba="0.69019607843137253944 0.69019607843137253944 0.69019607843137253944 1.0"/>
</material>
</visual>
<collision>
<origin xyz="7.951857074682654999e-15 5.0848214527832169551e-14 -0.060299903678891847436" rpy="3.141592653589708295 1.5707963267945217467 0" />
<geometry>
<mesh filename="package:///outer_knee_pulley.stl"/>
</geometry>
</collision>
<visual>
<origin xyz="1.3225145293323243017e-14 -0.14999999999989888089 -0.079399903678864375278" rpy="-1.570796326794827058 2.0769334551104144317e-14 3.1415926535897842342" />
<geometry>
<mesh filename="package:///outer_tibia.stl"/>
</geometry>
<material name="outer_tibia_material">
<color rgba="0.91764705882352937127 0.91764705882352937127 0.91764705882352937127 1.0"/>
</material>
</visual>
<collision>
<origin xyz="1.3225145293323243017e-14 -0.14999999999989888089 -0.079399903678864375278" rpy="-1.570796326794827058 2.0769334551104144317e-14 3.1415926535897842342" />
<geometry>
<mesh filename="package:///outer_tibia.stl"/>
</geometry>
</collision>
<visual>
<origin xyz="1.3391678747016865037e-14 -0.14999999999989901966 -0.079399903678864541812" rpy="1.5707963267948259478 -2.0835712847285112891e-14 2.521316488923770893e-13" />
<geometry>
<mesh filename="package:///outer_knee_2_mirror.stl"/>
</geometry>
<material name="outer_knee_2_mirror_material">
<color rgba="0.26274509803921569651 0.28235294117647058432 0.30196078431372547213 1.0"/>
</material>
</visual>
<collision>
<origin xyz="1.3391678747016865037e-14 -0.14999999999989901966 -0.079399903678864541812" rpy="1.5707963267948259478 -2.0835712847285112891e-14 2.521316488923770893e-13" />
<geometry>
<mesh filename="package:///outer_knee_2_mirror.stl"/>
</geometry>
</collision>
<inertial>
<origin xyz="0.00026312302307775767632 0.05702372964611684969 -0.03601485147580675561" rpy="0 0 0"/>
<mass value="0.13703698277488743362" />
<inertia ixx="0.00064596479719030341828" ixy="1.7196987936970865056e-06"  ixz="1.1842086374547852439e-06" iyy="0.00010718814902569959483" iyz="-7.3805580256844474695e-05" izz="0.00055786977795424747082" />
</inertial>
</link>

<link name="right_shaft_connector">
<visual>
<origin xyz="-0.14999999999994192978 -5.8632921636325166719e-14 0.030599999999981808418" rpy="1.5707963267948932273 -1.0323418292990469473e-14 -1.5707963267946640773" />
<geometry>
<mesh filename="package:///asc_2.stl"/>
</geometry>
<material name="asc_2_material">
<color rgba="0.26274509803921569651 0.28235294117647058432 0.30196078431372547213 1.0"/>
</material>
</visual>
<collision>
<origin xyz="-0.14999999999994192978 -5.8632921636325166719e-14 0.030599999999981808418" rpy="1.5707963267948932273 -1.0323418292990469473e-14 -1.5707963267946640773" />
<geometry>
<mesh filename="package:///asc_2.stl"/>
</geometry>
</collision>
<visual>
<origin xyz="-0.14999999999994192978 -5.8632921636325166719e-14 0.030599999999981808418" rpy="1.5707963267948932273 -1.0323418292990469473e-14 -1.5707963267946640773" />
<geometry>
<mesh filename="package:///asc_alu.stl"/>
</geometry>
<material name="asc_alu_material">
<color rgba="0.91764705882352937127 0.91764705882352937127 0.91764705882352937127 1.0"/>
</material>
</visual>
<collision>
<origin xyz="-0.14999999999994192978 -5.8632921636325166719e-14 0.030599999999981808418" rpy="1.5707963267948932273 -1.0323418292990469473e-14 -1.5707963267946640773" />
<geometry>
<mesh filename="package:///asc_alu.stl"/>
</geometry>
</collision>
<visual>
<origin xyz="-0.14999999999994190203 -5.9314772647749366378e-14 0.02060009632107523414" rpy="1.5707963267948932273 -1.0323418292990469473e-14 -1.5707963267946640773" />
<geometry>
<mesh filename="package:///asc_alu.stl"/>
</geometry>
<material name="asc_alu_material">
<color rgba="0.91764705882352937127 0.91764705882352937127 0.91764705882352937127 1.0"/>
</material>
</visual>
<collision>
<origin xyz="-0.14999999999994190203 -5.9314772647749366378e-14 0.02060009632107523414" rpy="1.5707963267948932273 -1.0323418292990469473e-14 -1.5707963267946640773" />
<geometry>
<mesh filename="package:///asc_alu.stl"/>
</geometry>
</collision>
<visual>
<origin xyz="-0.14999999999994192978 -5.8632921636325166719e-14 0.030599999999981808418" rpy="1.5707963267948932273 -1.0323418292990469473e-14 -1.5707963267946640773" />
<geometry>
<mesh filename="package:///asc_middle.stl"/>
</geometry>
<material name="asc_middle_material">
<color rgba="0.26274509803921569651 0.28235294117647058432 0.30196078431372547213 1.0"/>
</material>
</visual>
<collision>
<origin xyz="-0.14999999999994192978 -5.8632921636325166719e-14 0.030599999999981808418" rpy="1.5707963267948932273 -1.0323418292990469473e-14 -1.5707963267946640773" />
<geometry>
<mesh filename="package:///asc_middle.stl"/>
</geometry>
</collision>
<visual>
<origin xyz="-8.4654505627668186207e-15 -4.9426241678689435751e-14 -0.0014999999999980029308" rpy="1.5707963267948683583 1.5707963267947702146 0" />
<geometry>
<mesh filename="package:///inner_knee_pulley.stl"/>
</geometry>
<material name="inner_knee_pulley_material">
<color rgba="0.69019607843137253944 0.69019607843137253944 0.69019607843137253944 1.0"/>
</material>
</visual>
<collision>
<origin xyz="-8.4654505627668186207e-15 -4.9426241678689435751e-14 -0.0014999999999980029308" rpy="1.5707963267948683583 1.5707963267947702146 0" />
<geometry>
<mesh filename="package:///inner_knee_pulley.stl"/>
</geometry>
</collision>
<inertial>
<origin xyz="-0.00048040297333315111006 0.0016552291749313231481 -0.026309053335517747912" rpy="0 0 0"/>
<mass value="0.061462040916151317038" />
<inertia ixx="1.9498377459072192646e-05" ixy="5.9107554751625415657e-07"  ixz="-1.0354773174963797435e-07" iyy="1.5048956756514079202e-05" iyz="9.7869072411789750016e-08" izz="1.2983063169821774382e-05" />
</inertial>
</link>

<link name="ankle_shaft_2">
<visual>
<origin xyz="0.14999999999999971689 -0.025000000000000275474 -0.061399999999991544675" rpy="-1.570796326794896558 3.1813771400211875807e-16 -1.5707963267948825692" />
<geometry>
<mesh filename="package:///ankle_shaft.stl"/>
</geometry>
<material name="ankle_shaft_material">
<color rgba="0.49803921568627451677 0.49803921568627451677 0.49803921568627451677 1.0"/>
</material>
</visual>
<collision>
<origin xyz="0.14999999999999971689 -0.025000000000000275474 -0.061399999999991544675" rpy="-1.570796326794896558 3.1813771400211875807e-16 -1.5707963267948825692" />
<geometry>
<mesh filename="package:///ankle_shaft.stl"/>
</geometry>
</collision>
<visual>
<origin xyz="-0.2999999999999974909 -0.02499999999999841932 -0.061399999999992654898" rpy="-1.57079632679489678 2.5779048002196278141e-16 1.5707963267948921171" />
<geometry>
<mesh filename="package:///shaft_end.stl"/>
</geometry>
<material name="shaft_end_material">
<color rgba="0.91764705882352937127 0.91764705882352937127 0.91764705882352937127 1.0"/>
</material>
</visual>
<collision>
<origin xyz="-0.2999999999999974909 -0.02499999999999841932 -0.061399999999992654898" rpy="-1.57079632679489678 2.5779048002196278141e-16 1.5707963267948921171" />
<geometry>
<mesh filename="package:///shaft_end.stl"/>
</geometry>
</collision>
<visual>
<origin xyz="0.15000000000000096589 -0.025000000000000081185 -0.061399999999991988764" rpy="-1.57079632679489678 -7.9902994815375140242e-18 -1.570796326794896558" />
<geometry>
<mesh filename="package:///shaft_end.stl"/>
</geometry>
<material name="shaft_end_material">
<color rgba="0.91764705882352937127 0.91764705882352937127 0.91764705882352937127 1.0"/>
</material>
</visual>
<collision>
<origin xyz="0.15000000000000096589 -0.025000000000000081185 -0.061399999999991988764" rpy="-1.57079632679489678 -7.9902994815375140242e-18 -1.570796326794896558" />
<geometry>
<mesh filename="package:///shaft_end.stl"/>
</geometry>
</collision>
<inertial>
<origin xyz="-0.074999971953932556556 -0.025000034945366567118 -0.0034999919036190069166" rpy="0 0 0"/>
<mass value="0.027812191526678475134" />
<inertia ixx="7.4552320334516022311e-06" ixy="-2.1532398927852665615e-05"  ixz="-1.9837643979350899489e-12" iyy="6.3940111974528744264e-05" iyz="-1.6799621186702823405e-12" izz="7.1297798653936297919e-05" />
</inertial>
</link>

<link name="closing_right_2">
<inertial>
<origin xyz="0 0 0" rpy="0 0 0" />
<mass value="1e-9" />
<inertia ixx="0" ixy="0" ixz="0" iyy="0" iyz="0" izz="0" />
</inertial>
</link>
<joint name="closing_right_2_frame" type="fixed">
<origin xyz="-0.14999999999999633071 -0.049999999999998864797 -0.0069999999999999784617" rpy="1.3103514549253502123e-28 -9.3797041067719513922e-16 3.1415926535897895633" />
<parent link="ankle_shaft_2" />
<child link="closing_right_2" />
<axis xyz="0 0 0"/>
</joint>

<joint name="right_ankle_pitch_3" type="revolute">
<origin xyz="5.7537308251198737707e-14 0.02499999999997508035 -0.030799903678917495142" rpy="-3.1415926535897793492 7.2586854802179579745e-15 3.1415926535832938704" />
<parent link="right_shaft_connector" />
<child link="ankle_shaft_2" />
<axis xyz="0 0 1"/>
<limit effort="1" velocity="20" />
<joint_properties friction="0.0"/>
</joint>

<joint name="right_ankle_pitch_2" type="revolute">
<origin xyz="1.3883013479743998971e-14 9.7893915196323177952e-14 -0.048799903678874739787" rpy="3.1415926535897300553 6.9485480086530627972e-14 1.5707963267882383285" />
<parent link="right_tibia" />
<child link="right_shaft_connector" />
<axis xyz="0 0 1"/>
<limit effort="1" velocity="20" lower="-1.570796326794896558" upper="1.2375158973761830605"/>
<joint_properties friction="0.0"/>
</joint>

<link name="right_ankle">
<visual>
<origin xyz="-1.9081958235795365136e-17 0.30000000000000004441 -0.075399903678899898862" rpy="-1.570796326794896558 3.2992583534153017325e-31 2.3112295755706704928e-29" />
<geometry>
<mesh filename="package:///upper_foot.stl"/>
</geometry>
<material name="upper_foot_material">
<color rgba="0.26274509803921569651 0.28235294117647058432 0.30196078431372547213 1.0"/>
</material>
</visual>
<collision>
<origin xyz="-1.9081958235795365136e-17 0.30000000000000004441 -0.075399903678899898862" rpy="-1.570796326794896558 3.2992583534153017325e-31 2.3112295755706704928e-29" />
<geometry>
<mesh filename="package:///upper_foot.stl"/>
</geometry>
</collision>
<visual>
<origin xyz="-1.9081958235795365136e-17 0.30000000000000004441 -0.075399903678899898862" rpy="-1.570796326794896558 3.2992583534153017325e-31 2.3112295755706704928e-29" />
<geometry>
<mesh filename="package:///ankle_alu.stl"/>
</geometry>
<material name="ankle_alu_material">
<color rgba="0.91764705882352937127 0.91764705882352937127 0.91764705882352937127 1.0"/>
</material>
</visual>
<collision>
<origin xyz="-1.9081958235795365136e-17 0.30000000000000004441 -0.075399903678899898862" rpy="-1.570796326794896558 3.2992583534153017325e-31 2.3112295755706704928e-29" />
<geometry>
<mesh filename="package:///ankle_alu.stl"/>
</geometry>
</collision>
<visual>
<origin xyz="5.314387911447444925e-18 0.2999999999999999889 -0.065399903678899834469" rpy="-1.570796326794896336 -1.8318046936993005495e-16 1.2408649162399621602e-28" />
<geometry>
<mesh filename="package:///ankle_alu.stl"/>
</geometry>
<material name="ankle_alu_material">
<color rgba="0.91764705882352937127 0.91764705882352937127 0.91764705882352937127 1.0"/>
</material>
</visual>
<collision>
<origin xyz="5.314387911447444925e-18 0.2999999999999999889 -0.065399903678899834469" rpy="-1.570796326794896336 -1.8318046936993005495e-16 1.2408649162399621602e-28" />
<geometry>
<mesh filename="package:///ankle_alu.stl"/>
</geometry>
</collision>
<visual>
<origin xyz="-1.9081958235795365136e-17 0.30000000000000004441 -0.075399903678899898862" rpy="-1.570796326794896558 3.2992583534153017325e-31 2.3112295755706704928e-29" />
<geometry>
<mesh filename="package:///ankle.stl"/>
</geometry>
<material name="ankle_material">
<color rgba="0.26274509803921569651 0.28235294117647058432 0.30196078431372547213 1.0"/>
</material>
</visual>
<collision>
<origin xyz="-1.9081958235795365136e-17 0.30000000000000004441 -0.075399903678899898862" rpy="-1.570796326794896558 3.2992583534153017325e-31 2.3112295755706704928e-29" />
<geometry>
<mesh filename="package:///ankle.stl"/>
</geometry>
</collision>
<inertial>
<origin xyz="0.019112322181729462373 -0.015205870574052022734 -0.018224201528334392497" rpy="0 0 0"/>
<mass value="0.030363454605670948949" />
<inertia ixx="6.4880461468822524397e-06" ixy="3.3239185330133210227e-07"  ixz="-2.5433532902241856299e-07" iyy="9.3931085566719588838e-06" iyz="2.2738311301941005605e-07" izz="1.1963219846378346186e-05" />
</inertial>
</link>

<link name="closing_right_1">
<inertial>
<origin xyz="0 0 0" rpy="0 0 0" />
<mass value="1e-9" />
<inertia ixx="0" ixy="0" ixz="0" iyy="0" iyz="0" izz="0" />
</inertial>
</link>
<joint name="closing_right_1_frame" type="fixed">
<origin xyz="0.024999999999999994449 -1.1102230246251565404e-16 -0.020999903678907916316" rpy="-7.3769885253638019017e-17 -2.4589961751229850247e-17 2.3112295755706704928e-29" />
<parent link="right_ankle" />
<child link="closing_right_1" />
<axis xyz="0 0 0"/>
</joint>

<link name="right_foot">
<visual>
<origin xyz="0.057899999999992041166 0.33250000000000007327 0.0065000000000000092426" rpy="-1.570796326794896558 -1.570796326794896558 0" />
<geometry>
<mesh filename="package:///foot_alu.stl"/>
</geometry>
<material name="foot_alu_material">
<color rgba="0.91764705882352937127 0.91764705882352937127 0.91764705882352937127 1.0"/>
</material>
</visual>
<collision>
<origin xyz="0.057899999999992041166 0.33250000000000007327 0.0065000000000000092426" rpy="-1.570796326794896558 -1.570796326794896558 0" />
<geometry>
<mesh filename="package:///foot_alu.stl"/>
</geometry>
</collision>
<visual>
<origin xyz="0.057899999999992041166 0.33250000000000007327 0.0065000000000000092426" rpy="-1.570796326794896558 -1.570796326794896558 0" />
<geometry>
<mesh filename="package:///lower_foot.stl"/>
</geometry>
<material name="lower_foot_material">
<color rgba="0.26274509803921569651 0.28235294117647058432 0.30196078431372547213 1.0"/>
</material>
</visual>
<collision>
<origin xyz="0.057899999999992041166 0.33250000000000007327 0.0065000000000000092426" rpy="-1.570796326794896558 -1.570796326794896558 0" />
<geometry>
<mesh filename="package:///lower_foot.stl"/>
</geometry>
</collision>
<inertial>
<origin xyz="7.2744567820538032265e-05 -0.015405356144870454432 0.0046860616625078880051" rpy="0 0 0"/>
<mass value="0.055361091085330049744" />
<inertia ixx="6.8711126907459936812e-05" ixy="-5.2824061284447341932e-08"  ixz="-8.3304804788334828825e-08" iyy="8.3573527857427074104e-05" iyz="-2.3992747304712930186e-06" izz="1.7621203254795958661e-05" />
</inertial>
</link>

<link name="right">
<inertial>
<origin xyz="0 0 0" rpy="0 0 0" />
<mass value="1e-9" />
<inertia ixx="0" ixy="0" ixz="0" iyy="0" iyz="0" izz="0" />
</inertial>
</link>
<joint name="right_frame" type="fixed">
<origin xyz="8.3266726846886740532e-17 -0.018500000000000182965 -0.00075698915673005212623" rpy="-1.570796326794896558 1.570796326794896558 0" />
<parent link="right_foot" />
<child link="right" />
<axis xyz="0 0 0"/>
</joint>

<joint name="right_ankle_roll" type="revolute">
<origin xyz="-0.0065000000000001272038 -0.032499999999999029665 -0.01749990367890758014" rpy="-1.6386994296483263268e-27 1.5707963267948956698 0" />
<parent link="right_ankle" />
<child link="right_foot" />
<axis xyz="0 0 1"/>
<limit effort="1" velocity="20" lower="-0.52359877559829881566" upper="0.1745329251994329478"/>
<joint_properties friction="0.0"/>
</joint>

<joint name="right_ankle_pitch_4" type="revolute">
<origin xyz="4.6832013725719971683e-16 0.15000000000000299205 -0.0040000000000158519864" rpy="6.9436156178235627099e-14 6.3059604428588073261e-14 -3.141592653589638573" />
<parent link="right_tibia" />
<child link="right_ankle" />
<axis xyz="0 0 1"/>
<limit effort="1" velocity="20" lower="-1.2375158973761830605" upper="1.570796326794896558"/>
<joint_properties friction="0.0"/>
</joint>

<joint name="right_knee_2" type="revolute">
<origin xyz="-4.922167006389468494e-13 0.15000000000018082202 0.046499903678870690982" rpy="-8.733564085496093242e-16 2.1743913325908184736e-16 7.2423944486828269001e-13" />
<parent link="right_femur" />
<child link="right_tibia" />
<axis xyz="0 0 1"/>
<limit effort="1" velocity="20" lower="0" upper="2.356194490192344837"/>
<joint_properties friction="0.0"/>
</joint>

<link name="motor_pulley_6">
<visual>
<origin xyz="1.3877787807814456755e-17 6.9388939039072283776e-18 -0.019400000000000056088" rpy="-1.570796326794896558 -1.570796326794896558 0" />
<geometry>
<mesh filename="package:///motor_pulley.stl"/>
</geometry>
<material name="motor_pulley_material">
<color rgba="0.69019607843137253944 0.69019607843137253944 0.69019607843137253944 1.0"/>
</material>
</visual>
<collision>
<origin xyz="1.3877787807814456755e-17 6.9388939039072283776e-18 -0.019400000000000056088" rpy="-1.570796326794896558 -1.570796326794896558 0" />
<geometry>
<mesh filename="package:///motor_pulley.stl"/>
</geometry>
</collision>
<inertial>
<origin xyz="-5.7160141462319270093e-16 4.6478062022555736033e-05 -0.010286242910584462995" rpy="0 0 0"/>
<mass value="0.068767168773007730787" />
<inertia ixx="9.6751984178822032399e-06" ixy="-6.4096157715202731957e-22"  ixz="-2.4567264192824921944e-20" iyy="9.6433853220652272347e-06" iyz="-2.76674782590276804e-08" izz="1.5466315743353463972e-05" />
</inertial>
</link>

<joint name="right_ankle_pitch_1" type="revolute">
<origin xyz="-4.8647140664784363295e-13 0.080000000000202506345 0.018299999999978916465" rpy="4.4539911443551959561e-16 -1.9360994195986860955e-15 -1.1372251246499935906" />
<parent link="right_femur" />
<child link="motor_pulley_6" />
<axis xyz="0 0 1"/>
<limit effort="1" velocity="20" />
<joint_properties friction="0.0"/>
</joint>

<joint name="right_hip_pitch" type="revolute">
<origin xyz="-0.028499903678899846104 0.057999998778099991215 -0.026999998778099998376" rpy="6.1232339957388072135e-17 1.570796326794896558 0" />
<parent link="right_lower_hip" />
<child link="right_femur" />
<axis xyz="0 0 1"/>
<limit effort="1" velocity="20" lower="-1.9198621771937625091" upper="1.0471975511965976313"/>
<joint_properties friction="0.0"/>
</joint>

<joint name="right_hip_roll_2" type="revolute">
<origin xyz="0.036349989645413194328 2.9420910152566648321e-15 0.12149999999999683276" rpy="1.5707963267948972241 -1.3553674556756956347e-13 1.5707963267948970021" />
<parent link="right_upper_hip" />
<child link="right_lower_hip" />
<axis xyz="0 0 1"/>
<limit effort="1" velocity="20" lower="-0.1745329251994329478" upper="1.0471975511965976313"/>
<joint_properties friction="0.0"/>
</joint>

<joint name="right_hip_yaw" type="revolute">
<origin xyz="0.0093499908672991186714 -0.18139990367880462485 0.1794999987780965256" rpy="-3.1415926535895533078 -4.5025549804522808348e-16 3.1415926535897784611" />
<parent link="pelvis" />
<child link="right_upper_hip" />
<axis xyz="0 0 1"/>
<limit effort="1" velocity="20" lower="-1.570796326794896558" upper="1.570796326794896558"/>
<joint_properties friction="0.0"/>
</joint>


</robot>
